Workbook

Sheet 입력
A1: 수출서류 입력시트
A2: 노란색 칸만 채우면 Commercial Invoice 와 Packing List 두 시트가 자동으로 완성됨. 흰색 칸은 수식이므로 건드리지 말 것.
A4: ■ 거래 기본정보
A5: Invoice No. | B5: SY-2026-0001 | C5: 송장번호. 회사 규칙대로
A6: Invoice Date | B6: 2026-08-31 | C6: YYYY-MM-DD
A7: P/O No. | B7: PO-8842 | C7: 바이어 주문번호. 없으면 공란
A8: 가격조건 (Incoterms) | B8: FOB BUSAN | C8: 반드시 지정장소까지. 예) FOB BUSAN
A9: Incoterms 버전 | B9: Incoterms(R) 2020 | C9: 2020 으로 통일
A10: 결제조건 (Payment) | B10: T/T 30% in advance, 70% after B/L | C10: 구체적으로
A11: 결제통화 (Currency) | B11: USD | C11: USD / EUR / CNY 등
A12: 원산지 (Country of Origin) | B12: REPUBLIC OF KOREA
A13: 선적항 (Port of Loading) | B13: BUSAN, KOREA
A14: 도착항 (Port of Discharge) | B14: HO CHI MINH, VIETNAM
A15: 최종목적지 (Final Destination) | B15: HO CHI MINH, VIETNAM
A16: 선박명/항차 (Vessel/Voyage) | B16: T.B.A. | C16: 미정이면 T.B.A.
A17: 출항예정일 (ETD) | B17: T.B.A. | C17: 미정이면 T.B.A.
A19: ■ 수출자 (Shipper / Exporter)
A20: 상호 | B20: SY COSMETICS CO., LTD. | C20: 통관고유부호 등록 상호와 동일하게
A21: 주소1 | B21: 123, TEHERAN-RO, GANGNAM-GU
A22: 주소2 | B22: SEOUL, 06234, REPUBLIC OF KOREA
A23: 담당자/연락처 | B23: J.S. LEE / +82-2-1234-5678
A24: 통관고유부호 | B24: 1234567890123 | C24: 유니패스 발급
A26: ■ 수입자 (Consignee)
A27: 상호 | B27: ABC TRADING CO., LTD. | C27: 해외거래처부호 등록 상호와 동일하게
A28: 주소1 | B28: 456 NGUYEN HUE STREET, DISTRICT 1
A29: 주소2 | B29: HO CHI MINH CITY, VIETNAM
A30: 담당자/연락처 | B30: MR. TRAN / +84-28-1234-5678
A31: 해외거래처부호 | B31: VN1234567 | C31: 유니패스 등록
A33: ■ 착화통지처 (Notify Party)
A34: 표기 | B34: SAME AS CONSIGNEE | C34: 수입자와 같으면 SAME AS CONSIGNEE
A36: ■ 포장 총괄
A37: 포장단위 | B37: CTNS | C37: CTNS(박스) / PLTS(팔레트) 등
A38: 총 부피 (CBM) | B38: 2.45 | C38: 숫자만
A41: ■ 품목 (아래 표만 채우면 됨. 최대 15행)
A42: No. | B42: 품명 (Description) | C42: 규격 (Spec) | D42: HS CODE | E42: 수량 | F42: 단위 | G42: 단가 | H42: 금액 | I42: 순중량 N.W.(kg) | J42: 총중량 G.W.(kg) | K42: 포장수량
A43: 1 | B43: FACIAL CLEANSING FOAM 150ML | C43: MODEL SY-CF150 | D43: 3304.99 | E43: 1200 | F43: PCS | G43: 3.5 | H43: =IF(E43="","",E43*G43) -> 4200 | I43: 180 | J43: 210.5 | K43: 50
H44: =IF(E44="","",E44*G44)
H45: =IF(E45="","",E45*G45)
H46: =IF(E46="","",E46*G46)
H47: =IF(E47="","",E47*G47)
...

Sheet Commercial Invoice
A1: COMMERCIAL INVOICE
A3: Shipper / Exporter | E3: Invoice No. | F3: =입력!B5 -> SY-2026-0001 | G3: Date | H3: =입력!B6 -> 2026-08-31
A4: =입력!B20 -> SY COSMETICS CO., LTD. | E4: P/O No. | F4: =입력!B7 -> PO-8842
A5: =입력!B21 -> 123, TEHERAN-RO, GANGNAM-GU
A6: =입력!B22 -> SEOUL, 06234, REPUBLIC OF KOREA
A7: =입력!B23 -> J.S. LEE / +82-2-1234-5678
A8: Consignee | E8: Notify Party
A9: =입력!B27 -> ABC TRADING CO., LTD. | E9: =입력!B34 -> SAME AS CONSIGNEE
A10: =입력!B28 -> 456 NGUYEN HUE STREET, DISTRICT 1
A11: =입력!B29 -> HO CHI MINH CITY, VIETNAM
A12: =입력!B30 -> MR. TRAN / +84-28-1234-5678
A13: Port of Loading | B13: =입력!B13 -> BUSAN, KOREA | E13: Port of Discharge | F13: =입력!B14 -> HO CHI MINH, VIETNAM
A14: Final Destination | B14: =입력!B15 -> HO CHI MINH, VIETNAM | E14: Vessel / Voyage | F14: =입력!B16 -> T.B.A.
A15: ETD | B15: =입력!B17 -> T.B.A. | E15: Country of Origin | F15: =입력!B12 -> REPUBLIC OF KOREA
A16: Price Term | B16: =입력!B8 -> FOB BUSAN | E16: Incoterms | F16: =입력!B9 -> Incoterms(R) 2020
A17: Payment Term | B17: =입력!B10 -> T/T 30% in advance, 70% after B/L | E17: Currency | F17: =입력!B11 -> USD
A19: No. | B19: Description | C19: Spec | D19: HS CODE | E19: Q'ty | F19: Unit | G19: Unit Price | H19: Amount
A20: =IF(입력!$B$43="","",입력!A43) -> 1 | B20: =IF(입력!$B$43="","",입력!B43) -> FACIAL CLEANSING FOAM 150ML | C20: =IF(입력!$B$43="","",입력!C43) -> MODEL SY-CF150 | D20: =IF(입력!$B$43="","",입력!D43) -> 3304.99 | E20: =IF(입력!$B$43="","",입력!E43) -> 1200 | F20: =IF(입력!$B$43="","",입력!F43) -> PCS | G20: =IF(입력!$B$43="","",입력!G43) -> 3.5 | H20: =IF(입력!$B$43="","",입력!H43) -> 4200
A21: =IF(입력!$B$44="","",입력!A44) | B21: =IF(입력!$B$44="","",입력!B44) | C21: =IF(입력!$B$44="","",입력!C44) | D21: =IF(입력!$B$44="","",입력!D44) | E21: =IF(입력!$B$44="","",입력!E44) | F21: =IF(입력!$B$44="","",입력!F44) | G21: =IF(입력!$B$44="","",입력!G44) | H21: =IF(입력!$B$44="","",입력!H44)
A22: =IF(입력!$B$45="","",입력!A45) | B22: =IF(입력!$B$45="","",입력!B45) | C22: =IF(입력!$B$45="","",입력!C45) | D22: =IF(입력!$B$45="","",입력!D45) | E22: =IF(입력!$B$45="","",입력!E45) | F22: =IF(입력!$B$45="","",입력!F45) | G22: =IF(입력!$B$45="","",입력!G45) | H22: =IF(입력!$B$45="","",입력!H45)
A23: =IF(입력!$B$46="","",입력!A46) | B23: =IF(입력!$B$46="","",입력!B46) | C23: =IF(입력!$B$46="","",입력!C46) | D23: =IF(입력!$B$46="","",입력!D46) | E23: =IF(입력!$B$46="","",입력!E46) | F23: =IF(입력!$B$46="","",입력!F46) | G23: =IF(입력!$B$46="","",입력!G46) | H23: =IF(입력!$B$46="","",입력!H46)
A24: =IF(입력!$B$47="","",입력!A47) | B24: =IF(입력!$B$47="","",입력!B47) | C24: =IF(입력!$B$47="","",입력!C47) | D24: =IF(입력!$B$47="","",입력!D47) | E24: =IF(입력!$B$47="","",입력!E47) | F24: =IF(입력!$B$47="","",입력!F47) | G24: =IF(입력!$B$47="","",입력!G47) | H24: =IF(입력!$B$47="","",입력!H47)
A25: =IF(입력!$B$48="","",입력!A48) | B25: =IF(입력!$B$48="","",입력!B48) | C25: =IF(입력!$B$48="","",입력!C48) | D25: =IF(입력!$B$48="","",입력!D48) | E25: =IF(입력!$B$48="","",입력!E48) | F25: =IF(입력!$B$48="","",입력!F48) | G25: =IF(입력!$B$48="","",입력!G48) | H25: =IF(입력!$B$48="","",입력!H48)
A26: =IF(입력!$B$49="","",입력!A49) | B26: =IF(입력!$B$49="","",입력!B49) | C26: =IF(입력!$B$49="","",입력!C49) | D26: =IF(입력!$B$49="","",입력!D49) | E26: =IF(입력!$B$49="","",입력!E49) | F26: =IF(입력!$B$49="","",입력!F49) | G26: =IF(입력!$B$49="","",입력!G49) | H26: =IF(입력!$B$49="","",입력!H49)
A27: =IF(입력!$B$50="","",입력!A50) | B27: =IF(입력!$B$50="","",입력!B50) | C27: =IF(입력!$B$50="","",입력!C50) | D27: =IF(입력!$B$50="","",입력!D50) | E27: =IF(입력!$B$50="","",입력!E50) | F27: =IF(입력!$B$50="","",입력!F50) | G27: =IF(입력!$B$50="","",입력!G50) | H27: =IF(입력!$B$50="","",입력!H50)
A28: =IF(입력!$B$51="","",입력!A51) | B28: =IF(입력!$B$51="","",입력!B51) | C28: =IF(입력!$B$51="","",입력!C51) | D28: =IF(입력!$B$51="","",입력!D51) | E28: =IF(입력!$B$51="","",입력!E51) | F28: =IF(입력!$B$51="","",입력!F51) | G28: =IF(입력!$B$51="","",입력!G51) | H28: =IF(입력!$B$51="","",입력!H51)
A29: =IF(입력!$B$52="","",입력!A52) | B29: =IF(입력!$B$52="","",입력!B52) | C29: =IF(입력!$B$52="","",입력!C52) | D29: =IF(입력!$B$52="","",입력!D52) | E29: =IF(입력!$B$52="","",입력!E52) | F29: =IF(입력!$B$52="","",입력!F52) | G29: =IF(입력!$B$52="","",입력!G52) | H29: =IF(입력!$B$52="","",입력!H52)
A30: =IF(입력!$B$53="","",입력!A53) | B30: =IF(입력!$B$53="","",입력!B53) | C30: =IF(입력!$B$53="","",입력!C53) | D30: =IF(입력!$B$53="","",입력!D53) | E30: =IF(입력!$B$53="","",입력!E53) | F30: =IF(입력!$B$53="","",입력!F53) | G30: =IF(입력!$B$53="","",입력!G53) | H30: =IF(입력!$B$53="","",입력!H53)
A31: =IF(입력!$B$54="","",입력!A54) | B31: =IF(입력!$B$54="","",입력!B54) | C31: =IF(입력!$B$54="","",입력!C54) | D31: =IF(입력!$B$54="","",입력!D54) | E31: =IF(입력!$B$54="","",입력!E54) | F31: =IF(입력!$B$54="","",입력!F54) | G31: =IF(입력!$B$54="","",입력!G54) | H31: =IF(입력!$B$54="","",입력!H54)
A32: =IF(입력!$B$55="","",입력!A55) | B32: =IF(입력!$B$55="","",입력!B55) | C32: =IF(입력!$B$55="","",입력!C55) | D32: =IF(입력!$B$55="","",입력!D55) | E32: =IF(입력!$B$55="","",입력!E55) | F32: =IF(입력!$B$55="","",입력!F55) | G32: =IF(입력!$B$55="","",입력!G55) | H32: =IF(입력!$B$55="","",입력!H55)
A33: =IF(입력!$B$56="","",입력!A56) | B33: =IF(입력!$B$56="","",입력!B56) | C33: =IF(입력!$B$56="","",입력!C56) | D33: =IF(입력!$B$56="","",입력!D56) | E33: =IF(입력!$B$56="","",입력!E56) | F33: =IF(입력!$B$56="","",입력!F56) | G33: =IF(입력!$B$56="","",입력!G56) | H33: =IF(입력!$B$56="","",입력!H56)
A34: =IF(입력!$B$57="","",입력!A57) | B34: =IF(입력!$B$57="","",입력!B57) | C34: =IF(입력!$B$57="","",입력!C57) | D34: =IF(입력!$B$57="","",입력!D57) | E34: =IF(입력!$B$57="","",입력!E57) | F34: =IF(입력!$B$57="","",입력!F57) | G34: =IF(입력!$B$57="","",입력!G57) | H34: =IF(입력!$B$57="","",입력!H57)
A35: TOTAL | E35: =입력!E58 -> 1200 | H35: =입력!H58 -> 4200
A37: Total Amount | B37: =입력!B11 & " " & TEXT(입력!H58,"#,##0.00") -> USD 4,200.00
A38: Price Term | B38: =입력!B8 & " " & 입력!B9 -> FOB BUSAN Incoterms(R) 2020
F40: =입력!B20 -> SY COSMETICS CO., LTD.
F41: Signed by
F42: ________________________

Sheet Packing List
A1: PACKING LIST
A3: Shipper / Exporter | E3: Invoice No. | F3: =입력!B5 -> SY-2026-0001 | G3: Date | H3: =입력!B6 -> 2026-08-31
A4: =입력!B20 -> SY COSMETICS CO., LTD. | E4: P/O No. | F4: =입력!B7 -> PO-8842
A5: =입력!B21 -> 123, TEHERAN-RO, GANGNAM-GU
A6: =입력!B22 -> SEOUL, 06234, REPUBLIC OF KOREA
A7: =입력!B23 -> J.S. LEE / +82-2-1234-5678
A8: Consignee | E8: Notify Party
A9: =입력!B27 -> ABC TRADING CO., LTD. | E9: =입력!B34 -> SAME AS CONSIGNEE
A10: =입력!B28 -> 456 NGUYEN HUE STREET, DISTRICT 1
A11: =입력!B29 -> HO CHI MINH CITY, VIETNAM
A12: =입력!B30 -> MR. TRAN / +84-28-1234-5678
A13: Port of Loading | B13: =입력!B13 -> BUSAN, KOREA | E13: Port of Discharge | F13: =입력!B14 -> HO CHI MINH, VIETNAM
A14: Final Destination | B14: =입력!B15 -> HO CHI MINH, VIETNAM | E14: Vessel / Voyage | F14: =입력!B16 -> T.B.A.
A15: ETD | B15: =입력!B17 -> T.B.A. | E15: Country of Origin | F15: =입력!B12 -> REPUBLIC OF KOREA
A16: Price Term | B16: =입력!B8 -> FOB BUSAN
A18: No. | B18: Description | C18: Spec | D18: HS CODE | E18: Q'ty | F18: Unit | G18: N.W.(kg) | H18: G.W.(kg) | I18: Packages
A19: =IF(입력!$B$43="","",입력!A43) -> 1 | B19: =IF(입력!$B$43="","",입력!B43) -> FACIAL CLEANSING FOAM 150ML | C19: =IF(입력!$B$43="","",입력!C43) -> MODEL SY-CF150 | D19: =IF(입력!$B$43="","",입력!D43) -> 3304.99 | E19: =IF(입력!$B$43="","",입력!E43) -> 1200 | F19: =IF(입력!$B$43="","",입력!F43) -> PCS | G19: =IF(입력!$B$43="","",입력!I43) -> 180 | H19: =IF(입력!$B$43="","",입력!J43) -> 210.5 | I19: =IF(입력!$B$43="","",입력!K43) -> 50
A20: =IF(입력!$B$44="","",입력!A44) | B20: =IF(입력!$B$44="","",입력!B44) | C20: =IF(입력!$B$44="","",입력!C44) | D20: =IF(입력!$B$44="","",입력!D44) | E20: =IF(입력!$B$44="","",입력!E44) | F20: =IF(입력!$B$44="","",입력!F44) | G20: =IF(입력!$B$44="","",입력!I44) | H20: =IF(입력!$B$44="","",입력!J44) | I20: =IF(입력!$B$44="","",입력!K44)
A21: =IF(입력!$B$45="","",입력!A45) | B21: =IF(입력!$B$45="","",입력!B45) | C21: =IF(입력!$B$45="","",입력!C45) | D21: =IF(입력!$B$45="","",입력!D45) | E21: =IF(입력!$B$45="","",입력!E45) | F21: =IF(입력!$B$45="","",입력!F45) | G21: =IF(입력!$B$45="","",입력!I45) | H21: =IF(입력!$B$45="","",입력!J45) | I21: =IF(입력!$B$45="","",입력!K45)
A22: =IF(입력!$B$46="","",입력!A46) | B22: =IF(입력!$B$46="","",입력!B46) | C22: =IF(입력!$B$46="","",입력!C46) | D22: =IF(입력!$B$46="","",입력!D46) | E22: =IF(입력!$B$46="","",입력!E46) | F22: =IF(입력!$B$46="","",입력!F46) | G22: =IF(입력!$B$46="","",입력!I46) | H22: =IF(입력!$B$46="","",입력!J46) | I22: =IF(입력!$B$46="","",입력!K46)
A23: =IF(입력!$B$47="","",입력!A47) | B23: =IF(입력!$B$47="","",입력!B47) | C23: =IF(입력!$B$47="","",입력!C47) | D23: =IF(입력!$B$47="","",입력!D47) | E23: =IF(입력!$B$47="","",입력!E47) | F23: =IF(입력!$B$47="","",입력!F47) | G23: =IF(입력!$B$47="","",입력!I47) | H23: =IF(입력!$B$47="","",입력!J47) | I23: =IF(입력!$B$47="","",입력!K47)
A24: =IF(입력!$B$48="","",입력!A48) | B24: =IF(입력!$B$48="","",입력!B48) | C24: =IF(입력!$B$48="","",입력!C48) | D24: =IF(입력!$B$48="","",입력!D48) | E24: =IF(입력!$B$48="","",입력!E48) | F24: =IF(입력!$B$48="","",입력!F48) | G24: =IF(입력!$B$48="","",입력!I48) | H24: =IF(입력!$B$48="","",입력!J48) | I24: =IF(입력!$B$48="","",입력!K48)
A25: =IF(입력!$B$49="","",입력!A49) | B25: =IF(입력!$B$49="","",입력!B49) | C25: =IF(입력!$B$49="","",입력!C49) | D25: =IF(입력!$B$49="","",입력!D49) | E25: =IF(입력!$B$49="","",입력!E49) | F25: =IF(입력!$B$49="","",입력!F49) | G25: =IF(입력!$B$49="","",입력!I49) | H25: =IF(입력!$B$49="","",입력!J49) | I25: =IF(입력!$B$49="","",입력!K49)
A26: =IF(입력!$B$50="","",입력!A50) | B26: =IF(입력!$B$50="","",입력!B50) | C26: =IF(입력!$B$50="","",입력!C50) | D26: =IF(입력!$B$50="","",입력!D50) | E26: =IF(입력!$B$50="","",입력!E50) | F26: =IF(입력!$B$50="","",입력!F50) | G26: =IF(입력!$B$50="","",입력!I50) | H26: =IF(입력!$B$50="","",입력!J50) | I26: =IF(입력!$B$50="","",입력!K50)
A27: =IF(입력!$B$51="","",입력!A51) | B27: =IF(입력!$B$51="","",입력!B51) | C27: =IF(입력!$B$51="","",입력!C51) | D27: =IF(입력!$B$51="","",입력!D51) | E27: =IF(입력!$B$51="","",입력!E51) | F27: =IF(입력!$B$51="","",입력!F51) | G27: =IF(입력!$B$51="","",입력!I51) | H27: =IF(입력!$B$51="","",입력!J51) | I27: =IF(입력!$B$51="","",입력!K51)
A28: =IF(입력!$B$52="","",입력!A52) | B28: =IF(입력!$B$52="","",입력!B52) | C28: =IF(입력!$B$52="","",입력!C52) | D28: =IF(입력!$B$52="","",입력!D52) | E28: =IF(입력!$B$52="","",입력!E52) | F28: =IF(입력!$B$52="","",입력!F52) | G28: =IF(입력!$B$52="","",입력!I52) | H28: =IF(입력!$B$52="","",입력!J52) | I28: =IF(입력!$B$52="","",입력!K52)
A29: =IF(입력!$B$53="","",입력!A53) | B29: =IF(입력!$B$53="","",입력!B53) | C29: =IF(입력!$B$53="","",입력!C53) | D29: =IF(입력!$B$53="","",입력!D53) | E29: =IF(입력!$B$53="","",입력!E53) | F29: =IF(입력!$B$53="","",입력!F53) | G29: =IF(입력!$B$53="","",입력!I53) | H29: =IF(입력!$B$53="","",입력!J53) | I29: =IF(입력!$B$53="","",입력!K53)
A30: =IF(입력!$B$54="","",입력!A54) | B30: =IF(입력!$B$54="","",입력!B54) | C30: =IF(입력!$B$54="","",입력!C54) | D30: =IF(입력!$B$54="","",입력!D54) | E30: =IF(입력!$B$54="","",입력!E54) | F30: =IF(입력!$B$54="","",입력!F54) | G30: =IF(입력!$B$54="","",입력!I54) | H30: =IF(입력!$B$54="","",입력!J54) | I30: =IF(입력!$B$54="","",입력!K54)
A31: =IF(입력!$B$55="","",입력!A55) | B31: =IF(입력!$B$55="","",입력!B55) | C31: =IF(입력!$B$55="","",입력!C55) | D31: =IF(입력!$B$55="","",입력!D55) | E31: =IF(입력!$B$55="","",입력!E55) | F31: =IF(입력!$B$55="","",입력!F55) | G31: =IF(입력!$B$55="","",입력!I55) | H31: =IF(입력!$B$55="","",입력!J55) | I31: =IF(입력!$B$55="","",입력!K55)
A32: =IF(입력!$B$56="","",입력!A56) | B32: =IF(입력!$B$56="","",입력!B56) | C32: =IF(입력!$B$56="","",입력!C56) | D32: =IF(입력!$B$56="","",입력!D56) | E32: =IF(입력!$B$56="","",입력!E56) | F32: =IF(입력!$B$56="","",입력!F56) | G32: =IF(입력!$B$56="","",입력!I56) | H32: =IF(입력!$B$56="","",입력!J56) | I32: =IF(입력!$B$56="","",입력!K56)
A33: =IF(입력!$B$57="","",입력!A57) | B33: =IF(입력!$B$57="","",입력!B57) | C33: =IF(입력!$B$57="","",입력!C57) | D33: =IF(입력!$B$57="","",입력!D57) | E33: =IF(입력!$B$57="","",입력!E57) | F33: =IF(입력!$B$57="","",입력!F57) | G33: =IF(입력!$B$57="","",입력!I57) | H33: =IF(입력!$B$57="","",입력!J57) | I33: =IF(입력!$B$57="","",입력!K57)
A34: TOTAL | E34: =입력!E58 -> 1200 | G34: =입력!I58 -> 180 | H34: =입력!J58 -> 210.5 | I34: =입력!K58 -> 50
A36: Total Packages | B36: =입력!K58 & " " & 입력!B37 -> 50 CTNS
A37: Total Measurement (CBM) | B37: =입력!B38 -> 2.45
F39: =입력!B20 -> SY COSMETICS CO., LTD.
F40: Signed by
F41: ________________________
